Workbook

Sheet Summary
A1: Milestone 1 progress by member (updates from the Tracker sheet)
A3: Member | B3: Mandatory | C3: Done | D3: In Review | E3: In Progress | F3: Not Started | G3: Bonus | H3: Bonus done | I3: % mandatory done
A4: Hazem | B4: =COUNTIFS(Tracker!$H$2:$H$116,$A4,Tracker!$B$2:$B$116,"Mandatory") -> 13 | C4: =COUNTIFS(Tracker!$H$2:$H$116,$A4,Tracker!$B$2:$B$116,"Mandatory",Tracker!$J$2:$J$116,"Done") -> 0 | D4: =COUNTIFS(Tracker!$H$2:$H$116,$A4,Tracker!$B$2:$B$116,"Mandatory",Tracker!$J$2:$J$116,"In Review") -> 0 | E4: =COUNTIFS(Tracker!$H$2:$H$116,$A4,Tracker!$B$2:$B$116,"Mandatory",Tracker!$J$2:$J$116,"In Progress") -> 0 | F4: =COUNTIFS(Tracker!$H$2:$H$116,$A4,Tracker!$B$2:$B$116,"Mandatory",Tracker!$J$2:$J$116,"Not Started") -> 13 | G4: =COUNTIFS(Tracker!$H$2:$H$116,$A4,Tracker!$B$2:$B$116,"Bonus") -> 2 | H4: =COUNTIFS(Tracker!$H$2:$H$116,$A4,Tracker!$B$2:$B$116,"Bonus",Tracker!$J$2:$J$116,"Done") -> 0 | I4: =IF(B4=0,0,C4/B4) -> 0
A5: Aabsy | B5: =COUNTIFS(Tracker!$H$2:$H$116,$A5,Tracker!$B$2:$B$116,"Mandatory") -> 11 | C5: =COUNTIFS(Tracker!$H$2:$H$116,$A5,Tracker!$B$2:$B$116,"Mandatory",Tracker!$J$2:$J$116,"Done") -> 0 | D5: =COUNTIFS(Tracker!$H$2:$H$116,$A5,Tracker!$B$2:$B$116,"Mandatory",Tracker!$J$2:$J$116,"In Review") -> 0 | E5: =COUNTIFS(Tracker!$H$2:$H$116,$A5,Tracker!$B$2:$B$116,"Mandatory",Tracker!$J$2:$J$116,"In Progress") -> 0 | F5: =COUNTIFS(Tracker!$H$2:$H$116,$A5,Tracker!$B$2:$B$116,"Mandatory",Tracker!$J$2:$J$116,"Not Started") -> 11 | G5: =COUNTIFS(Tracker!$H$2:$H$116,$A5,Tracker!$B$2:$B$116,"Bonus") -> 2 | H5: =COUNTIFS(Tracker!$H$2:$H$116,$A5,Tracker!$B$2:$B$116,"Bonus",Tracker!$J$2:$J$116,"Done") -> 0 | I5: =IF(B5=0,0,C5/B5) -> 0
A6: Memo | B6: =COUNTIFS(Tracker!$H$2:$H$116,$A6,Tracker!$B$2:$B$116,"Mandatory") -> 11 | C6: =COUNTIFS(Tracker!$H$2:$H$116,$A6,Tracker!$B$2:$B$116,"Mandatory",Tracker!$J$2:$J$116,"Done") -> 0 | D6: =COUNTIFS(Tracker!$H$2:$H$116,$A6,Tracker!$B$2:$B$116,"Mandatory",Tracker!$J$2:$J$116,"In Review") -> 0 | E6: =COUNTIFS(Tracker!$H$2:$H$116,$A6,Tracker!$B$2:$B$116,"Mandatory",Tracker!$J$2:$J$116,"In Progress") -> 0 | F6: =COUNTIFS(Tracker!$H$2:$H$116,$A6,Tracker!$B$2:$B$116,"Mandatory",Tracker!$J$2:$J$116,"Not Started") -> 11 | G6: =COUNTIFS(Tracker!$H$2:$H$116,$A6,Tracker!$B$2:$B$116,"Bonus") -> 1 | H6: =COUNTIFS(Tracker!$H$2:$H$116,$A6,Tracker!$B$2:$B$116,"Bonus",Tracker!$J$2:$J$116,"Done") -> 0 | I6: =IF(B6=0,0,C6/B6) -> 0
A7: Moharm | B7: =COUNTIFS(Tracker!$H$2:$H$116,$A7,Tracker!$B$2:$B$116,"Mandatory") -> 15 | C7: =COUNTIFS(Tracker!$H$2:$H$116,$A7,Tracker!$B$2:$B$116,"Mandatory",Tracker!$J$2:$J$116,"Done") -> 0 | D7: =COUNTIFS(Tracker!$H$2:$H$116,$A7,Tracker!$B$2:$B$116,"Mandatory",Tracker!$J$2:$J$116,"In Review") -> 0 | E7: =COUNTIFS(Tracker!$H$2:$H$116,$A7,Tracker!$B$2:$B$116,"Mandatory",Tracker!$J$2:$J$116,"In Progress") -> 0 | F7: =COUNTIFS(Tracker!$H$2:$H$116,$A7,Tracker!$B$2:$B$116,"Mandatory",Tracker!$J$2:$J$116,"Not Started") -> 15 | G7: =COUNTIFS(Tracker!$H$2:$H$116,$A7,Tracker!$B$2:$B$116,"Bonus") -> 2 | H7: =COUNTIFS(Tracker!$H$2:$H$116,$A7,Tracker!$B$2:$B$116,"Bonus",Tracker!$J$2:$J$116,"Done") -> 0 | I7: =IF(B7=0,0,C7/B7) -> 0
A8: Hasan | B8: =COUNTIFS(Tracker!$H$2:$H$116,$A8,Tracker!$B$2:$B$116,"Mandatory") -> 9 | C8: =COUNTIFS(Tracker!$H$2:$H$116,$A8,Tracker!$B$2:$B$116,"Mandatory",Tracker!$J$2:$J$116,"Done") -> 0 | D8: =COUNTIFS(Tracker!$H$2:$H$116,$A8,Tracker!$B$2:$B$116,"Mandatory",Tracker!$J$2:$J$116,"In Review") -> 0 | E8: =COUNTIFS(Tracker!$H$2:$H$116,$A8,Tracker!$B$2:$B$116,"Mandatory",Tracker!$J$2:$J$116,"In Progress") -> 0 | F8: =COUNTIFS(Tracker!$H$2:$H$116,$A8,Tracker!$B$2:$B$116,"Mandatory",Tracker!$J$2:$J$116,"Not Started") -> 9 | G8: =COUNTIFS(Tracker!$H$2:$H$116,$A8,Tracker!$B$2:$B$116,"Bonus") -> 2 | H8: =COUNTIFS(Tracker!$H$2:$H$116,$A8,Tracker!$B$2:$B$116,"Bonus",Tracker!$J$2:$J$116,"Done") -> 0 | I8: =IF(B8=0,0,C8/B8) -> 0
A9: Rawda | B9: =COUNTIFS(Tracker!$H$2:$H$116,$A9,Tracker!$B$2:$B$116,"Mandatory") -> 13 | C9: =COUNTIFS(Tracker!$H$2:$H$116,$A9,Tracker!$B$2:$B$116,"Mandatory",Tracker!$J$2:$J$116,"Done") -> 0 | D9: =COUNTIFS(Tracker!$H$2:$H$116,$A9,Tracker!$B$2:$B$116,"Mandatory",Tracker!$J$2:$J$116,"In Review") -> 0 | E9: =COUNTIFS(Tracker!$H$2:$H$116,$A9,Tracker!$B$2:$B$116,"Mandatory",Tracker!$J$2:$J$116,"In Progress") -> 0 | F9: =COUNTIFS(Tracker!$H$2:$H$116,$A9,Tracker!$B$2:$B$116,"Mandatory",Tracker!$J$2:$J$116,"Not Started") -> 13 | G9: =COUNTIFS(Tracker!$H$2:$H$116,$A9,Tracker!$B$2:$B$116,"Bonus") -> 1 | H9: =COUNTIFS(Tracker!$H$2:$H$116,$A9,Tracker!$B$2:$B$116,"Bonus",Tracker!$J$2:$J$116,"Done") -> 0 | I9: =IF(B9=0,0,C9/B9) -> 0
A10: Lojy | B10: =COUNTIFS(Tracker!$H$2:$H$116,$A10,Tracker!$B$2:$B$116,"Mandatory") -> 11 | C10: =COUNTIFS(Tracker!$H$2:$H$116,$A10,Tracker!$B$2:$B$116,"Mandatory",Tracker!$J$2:$J$116,"Done") -> 0 | D10: =COUNTIFS(Tracker!$H$2:$H$116,$A10,Tracker!$B$2:$B$116,"Mandatory",Tracker!$J$2:$J$116,"In Review") -> 0 | E10: =COUNTIFS(Tracker!$H$2:$H$116,$A10,Tracker!$B$2:$B$116,"Mandatory",Tracker!$J$2:$J$116,"In Progress") -> 0 | F10: =COUNTIFS(Tracker!$H$2:$H$116,$A10,Tracker!$B$2:$B$116,"Mandatory",Tracker!$J$2:$J$116,"Not Started") -> 11 | G10: =COUNTIFS(Tracker!$H$2:$H$116,$A10,Tracker!$B$2:$B$116,"Bonus") -> 0 | H10: =COUNTIFS(Tracker!$H$2:$H$116,$A10,Tracker!$B$2:$B$116,"Bonus",Tracker!$J$2:$J$116,"Done") -> 0 | I10: =IF(B10=0,0,C10/B10) -> 0
A11: Hafez | B11: =COUNTIFS(Tracker!$H$2:$H$116,$A11,Tracker!$B$2:$B$116,"Mandatory") -> 13 | C11: =COUNTIFS(Tracker!$H$2:$H$116,$A11,Tracker!$B$2:$B$116,"Mandatory",Tracker!$J$2:$J$116,"Done") -> 0 | D11: =COUNTIFS(Tracker!$H$2:$H$116,$A11,Tracker!$B$2:$B$116,"Mandatory",Tracker!$J$2:$J$116,"In Review") -> 0 | E11: =COUNTIFS(Tracker!$H$2:$H$116,$A11,Tracker!$B$2:$B$116,"Mandatory",Tracker!$J$2:$J$116,"In Progress") -> 0 | F11: =COUNTIFS(Tracker!$H$2:$H$116,$A11,Tracker!$B$2:$B$116,"Mandatory",Tracker!$J$2:$J$116,"Not Started") -> 13 | G11: =COUNTIFS(Tracker!$H$2:$H$116,$A11,Tracker!$B$2:$B$116,"Bonus") -> 1 | H11: =COUNTIFS(Tracker!$H$2:$H$116,$A11,Tracker!$B$2:$B$116,"Bonus",Tracker!$J$2:$J$116,"Done") -> 0 | I11: =IF(B11=0,0,C11/B11) -> 0
A12: Everyone | B12: =COUNTIFS(Tracker!$H$2:$H$116,$A12,Tracker!$B$2:$B$116,"Mandatory") -> 8 | C12: =COUNTIFS(Tracker!$H$2:$H$116,$A12,Tracker!$B$2:$B$116,"Mandatory",Tracker!$J$2:$J$116,"Done") -> 0 | D12: =COUNTIFS(Tracker!$H$2:$H$116,$A12,Tracker!$B$2:$B$116,"Mandatory",Tracker!$J$2:$J$116,"In Review") -> 0 | E12: =COUNTIFS(Tracker!$H$2:$H$116,$A12,Tracker!$B$2:$B$116,"Mandatory",Tracker!$J$2:$J$116,"In Progress") -> 0 | F12: =COUNTIFS(Tracker!$H$2:$H$116,$A12,Tracker!$B$2:$B$116,"Mandatory",Tracker!$J$2:$J$116,"Not Started") -> 8 | G12: =COUNTIFS(Tracker!$H$2:$H$116,$A12,Tracker!$B$2:$B$116,"Bonus") -> 0 | H12: =COUNTIFS(Tracker!$H$2:$H$116,$A12,Tracker!$B$2:$B$116,"Bonus",Tracker!$J$2:$J$116,"Done") -> 0 | I12: =IF(B12=0,0,C12/B12) -> 0
A13: Total | B13: =SUM(B4:B12) -> 104 | C13: =SUM(C4:C12) -> 0 | D13: =SUM(D4:D12) -> 0 | E13: =SUM(E4:E12) -> 0 | F13: =SUM(F4:F12) -> 104 | G13: =SUM(G4:G12) -> 11 | H13: =SUM(H4:H12) -> 0 | I13: =IF(B13=0,0,C13/B13) -> 0
A15: Change Status (column J) and Owner (column H) on the Tracker sheet. Rows shaded yellow are bonus requirements. "Everyone" = shared conventions (validation, pagination, UI rules).

Sheet Tracker
A1: ID | B1: Type | C1: Module | D1: Actor(s) | E1: Requirement | F1: Dependencies | G1: Complexity | H1: Owner | I1: Milestone | J1: Status | K1: Issue / PR link | L1: Test evidence | M1: Blocker / notes
A2: ACC-01 | B2: Mandatory | C2: Accounts & Admin | D2: Guest | E2: The system shall allow a guest to register by entering name, unique email, password and a mandatory terms-and-privacy consent checkbox. The password must have at least 8 characters, including at least one letter and one digit. The system shall reject the form with an inline error if the email is invalid or already registered, the password breaks these rules, or consent is not given. | G2: Low | H2: Hazem | I2: M1 | J2: Not Started
A3: ACC-04 | B3: Mandatory | C3: Accounts & Admin | D3: Registered User, Admin, Hotel Moderator, Airline Moderator | E3: The system shall allow a registered user, admin or moderator to log in with email and password and land on their role's home page. On failure it shall show a generic "invalid email or password" message. Suspended accounts shall see an "account suspended" message. | F3: ACC-01 | G3: Medium | H3: Hazem | I3: M1 | J3: Not Started
A4: ACC-05 | B4: Mandatory | C4: Accounts & Admin | D4: System | E4: After 5 consecutive failed login attempts, the system shall lock the account for 15 minutes and show a lockout message. A successful login resets the counter. | F4: ACC-04 | G4: Medium | H4: Hazem | I4: M1 | J4: Not Started
A5: ACC-06 | B5: Mandatory | C5: Accounts & Admin | D5: Any logged-in user | E5: The system shall allow a logged-in user to log out, which clears the authentication cookies and revokes the refresh token on the server. A session with no authenticated request for 30 minutes shall expire and require a new login. | F5: ACC-04, NEW-07 | G5: Medium | H5: Hazem | I5: M1 | J5: Not Started
A6: ACC-07a | B6: Mandatory | C6: Accounts & Admin | D6: Admin | E6: The system shall allow an admin to reset a user's or moderator's password to a temporary password. The account must set a new password that meets the password rules at its next login. | F6: ACC-04, ACC-14 | G6: Low | H6: Hasan | I6: M1 | J6: Not Started
A7: ACC-08 | B7: Mandatory | C7: Accounts & Admin | D7: Any logged-in user | E7: The system shall allow a logged-in user to change their password by entering the current password and a new one that meets the rules. | F7: ACC-04 | G7: Low | H7: Hazem | I7: M1 | J7: Not Started
A8: ACC-09 | B8: Mandatory | C8: Accounts & Admin | D8: Any logged-in user | E8: The system shall allow any logged-in user to edit name, phone number and preferred currency, saving only if all fields pass validation. | F8: ACC-04 | G8: Low | H8: Hazem | I8: M1 | J8: Not Started
A9: ACC-10 | B9: Mandatory | C9: Accounts & Admin | D9: Guest | E9: The system shall send a guest who attempts a restricted action (book, review, post) to login and return them to that action afterwards. | F9: ACC-04 | G9: Medium | H9: Hazem | I9: M2 only | J9: Not Started
A10: ACC-11 | B10: Mandatory | C10: Accounts & Admin | D10: System | E10: The system shall restrict access to bookings and private itineraries to their owner, except that admins may view all bookings (ACC-17) and moderators may view bookings for their own hotel or airline (FLT-29, HTL-22). Unauthorised requests shall be rejected (403/404). | F10: ACC-04 | G10: Medium | H10: Hazem | I10: M1 | J10: Not Started
A11: ACC-12 | B11: Mandatory | C11: Accounts & Admin | D11: Registered User | E11: The system shall allow a registered user to deactivate their own account after confirmation. Deactivation is blocked while the user has upcoming Confirmed bookings. A deactivated user cannot log in; their posts and public itineraries are hidden, and their comments and reviews are shown as "Deleted user". | F11: ACC-04, NEW-01 | G11: Medium | H11: Hazem | I11: M1 | J11: Not Started
A12: ACC-13 | B12: Mandatory | C12: Accounts & Admin | D12: Admin | E12: The system shall allow an admin to create a hotel or airline moderator account (name, email, role) linked to exactly one hotel or airline, with a temporary password set by the admin. The moderator must change the password on first login. | F12: ACC-04, FLT-01, HTL-01 | G12: Medium | H12: Hasan | I12: M1 | J12: Not Started
A13: ACC-14 | B13: Mandatory | C13: Accounts & Admin | D13: Admin | E13: The system shall allow an admin to view a paginated list of all accounts (name, email, role, status, registration date) and to search by name or email and filter by role and status. | F13: ACC-04 | G13: Low | H13: Hasan | I13: M1 | J13: Not Started
A14: ACC-15 | B14: Mandatory | C14: Accounts & Admin | D14: Admin | E14: The system shall allow an admin to suspend and reactivate a moderator account (a suspended moderator cannot log in) and, separately, to deactivate and reactivate a hotel or airline. A deactivated provider's listings are hidden from search and cannot be booked; existing Confirmed bookings remain valid. Affected parties receive an in-app notification. | F14: ACC-13, GEN-01 | G14: Medium | H14: Hasan | I14: M1 | J14: Not Started
... A61: PAY-03 | B61: Mandatory | C61: Payments & Policies | D61: System | E61: For every cancellation with a positive refund amount (user cancellations per the provider's tiers; provider-initiated cancellations at 100%), the system shall issue a refund through the Stripe Refunds API, record it, and show its status (Pending, Refunded, Failed) on the booking details. The user receives an in-app notification. | F61: PAY-01, FLT-09, HTL-10, GEN-01 | G61: Medium | H61: Memo | I61: M1 | J61: Not Started
A62: PAY-04 | B62: Mandatory | C62: Payments & Policies | D62: System | E62: All flight and hotel prices, payments and refunds shall use a single platform currency. | G62: Low | H62: Memo | I62: M1 | J62: Not Started
A63: ITN-01 | B63: Mandatory | C63: Itineraries | D63: Registered User | E63: The system shall allow a registered user to create an itinerary with a required title (max 100 characters), one or more countries selected from a predefined list and a start date; edit its title, countries and start date; and delete it after confirmation. It is private by default. When deleted, it disappears from public search, while clones previously made by other users remain unaffected. | F63: ACC-04, NEW-05 | G63: Low | H63: Moharm | I63: M1 | J63: Not Started
A64: ITN-03 | B64: Mandatory | C64: Itineraries | D64: Registered User | E64: The system shall allow a user to list their itineraries (title, countries, start date, days and visibility), most recently updated first, and open any itinerary to view its full details. | F64: ITN-01 | G64: Low | H64: Moharm | I64: M1 | J64: Not Started
A65: ITN-05 | B65: Mandatory | C65: Itineraries | D65: Registered User | E65: The system shall allow a user to add days to their itinerary and edit each day's city (selected from the predefined city list shared with hotels and airports) and notes. Days are numbered sequentially, their dates derive from the itinerary start date, and an itinerary has at most 60 days. | F65: ITN-01, NEW-05 | G65: Medium | H65: Moharm | I65: M1 | J65: Not Started
A66: ITN-07 | B66: Mandatory | C66: Itineraries | D66: Registered User | E66: The system shall allow a user to delete a day after confirmation. Remaining days are renumbered, and dates and budget totals are recalculated. | F66: ITN-05 | G66: Medium | H66: Moharm | I66: M1 | J66: Not Started
A67: ITN-08 | B67: Mandatory | C67: Itineraries | D67: Registered User | E67: The system shall allow a user to move a day to a new position, with days renumbered and dates and groupings recalculated. | F67: ITN-05 | G67: Medium | H67: Moharm | I67: M1 | J67: Not Started
A68: ITN-09 | B68: Mandatory | C68: Itineraries | D68: Registered User | E68: The system shall require each itinerary day to have a city and shall display consecutive days in the same city as a group, with the group's day count and budget subtotal. | F68: ITN-05 | G68: Medium | H68: Moharm | I68: M1 | J68: Not Started
A69: ITN-10 | B69: Mandatory | C69: Itineraries | D69: Registered User | E69: The system shall allow a user to add, edit and delete activities for an itinerary day, including name, description, optional time and optional cost. | F69: ITN-05 | G69: Low | H69: Moharm | I69: M1 | J69: Not Started
A70: ITN-12 | B70: Mandatory | C70: Itineraries | D70: Registered User | E70: The system shall allow a user to attach images to and remove images from an activity under the shared media-upload rule (GEN-08). | F70: ITN-10, GEN-08 | G70: Medium | H70: Moharm | I70: M1 | J70: Not Started
A71: ITN-14 | B71: Mandatory | C71: Itineraries | D71: Registered User | E71: The system shall allow a user to add, edit and delete non-negative budget entries for each day across food, accommodation, in-city transport and activities in a selected currency, and show the itinerary's total budget broken down by category and by day. Totals include budget entries, activity costs from ITN-10 (counted under Activities) and intercity transport entries (ITN-16). | F71: ITN-05, ITN-10, ITN-16 | G71: Medium | H71: Moharm | I71: M1 | J71: Not Started
A72: ITN-16 | B72: Mandatory | C72: Itineraries | D72: Registered User | E72: The system shall allow a user to add, edit and delete a transport cost entry (mode, from-city, to-city, amount, currency, day). | F72: ITN-05 | G72: Low | H72: Moharm | I72: M1 | J72: Not Started
A73: ITN-18 | B73: Mandatory | C73: Itineraries | D73: Registered User, System | E73: The system shall convert all itinerary budget amounts to the user's preferred currency (from the supported currency list) using exchange rates fetched once per day from a configured public exchange-rate API and cached in the database, and show the rate date. If the API is unavailable, the last cached rates are used. Booking prices are not converted (NEW-04). | F73: ITN-14, ACC-09, NEW-04 | G73: Medium | H73: Moharm | I73: M1 | J73: Not Started
A74: ITN-20 | B74: Mandatory | C74: Itineraries | D74: Registered User | E74: The system shall allow a user to set an itinerary's visibility to Public or Private. Public itineraries appear in shared search and are read-only to other users. Setting Private removes them immediately. | F74: ITN-01 | G74: Low | H74: Moharm | I74: M1 | J74: Not Started
... A88: BLG-12 | B88: Mandatory | C88: Blog | D88: Guest, Registered User | E88: The system shall provide a public author page showing the author's name, join date, published posts and public itineraries. | F88: BLG-01, ITN-20 | G88: Low | H88: Hafez | I88: M1 | J88: Not Started
A89: GEN-01 | B89: Mandatory | C89: Cross-cutting | D89: System | E89: The system shall show in-app notifications (unread count, notification list, mark as read) for booking confirmation, cancellation and refund, flight schedule change, and account or provider suspension. | G89: Medium | H89: Hasan | I89: M1 | J89: Not Started
A90: GEN-02 | B90: Mandatory | C90: Cross-cutting | D90: System | E90: The system shall show field-level validation messages on all forms. | G90: Low | H90: Everyone | I90: M1 | J90: Not Started
A91: GEN-03 | B91: Mandatory | C91: Cross-cutting | D91: System | E91: The system shall ask for confirmation before destructive actions (delete, cancel). | G91: Low | H91: Everyone | I91: M2 only | J91: Not Started
A92: GEN-04 | B92: Mandatory | C92: Cross-cutting | D92: System | E92: The system shall show friendly empty states when a list or search has no results. | G92: Low | H92: Everyone | I92: M2 only | J92: Not Started
A93: GEN-05 | B93: Mandatory | C93: Cross-cutting | D93: System | E93: The system shall paginate every list longer than 10 rows (page size 10). | G93: Low | H93: Everyone | I93: M1 | J93: Not Started
A94: GEN-06 | B94: Mandatory | C94: Cross-cutting | D94: System | E94: The system shall show flight times in each airport's local time zone. | F94: FLT-02, FLT-03 | G94: Medium | H94: Lojy | I94: M1 | J94: Not Started
A95: GEN-07 | B95: Mandatory | C95: Cross-cutting | D95: System | E95: The system shall keep an audit log of admin actions (suspensions, deletions). | F95: ACC-15, ACC-16, GEN-10 | G95: Low | H95: Hasan | I95: M1 | J95: Not Started
A96: GEN-08 | B96: Mandatory | C96: Cross-cutting | D96: System | E96: The system shall accept image uploads in JPG or PNG format, up to 5 MB each, with up to 5 images per post, activity or hotel and 1 logo per airline, stored on the server and served by URL. Uploads outside these limits are rejected with an error. | G96: Medium | H96: Hasan | I96: M1 | J96: Not Started
A97: GEN-09 | B97: Mandatory | C97: Cross-cutting | D97: Registered User | E97: The system shall allow a registered user to report a post, comment, review or itinerary with a reason, at most once per item. | F97: ACC-04 | G97: Low | H97: Hafez | I97: M1 | J97: Not Started
A98: GEN-10 | B98: Mandatory | C98: Cross-cutting | D98: Admin | E98: The system shall allow an admin to view the list of open reports and resolve each by dismissing it, hiding the content or deleting it, and to hide or delete any post, comment, review or itinerary directly. Hidden content is visible only to its author and admins. | F98: GEN-09 | G98: Medium | H98: Hafez | I98: M1 | J98: Not Started
A99: GEN-11 | B99: Mandatory | C99: Cross-cutting | D99: System | E99: Flight bookings and hotel reservations shall follow the lifecycle Pending Payment -> Confirmed -> Completed, with Pending Payment -> Expired (hold timeout) and Confirmed -> Cancelled (user or provider cancellation) as the only other transitions. | F99: FLT-22, HTL-18, PAY-01 | G99: Medium | H99: Aabsy | I99: M1 | J99: Not Started
...

Sheet Hazem
A1: ID | B1: Type | C1: Module | D1: Requirement | E1: Dependencies | F1: Complexity | G1: Milestone | H1: Status
A2: ACC-01 | B2: Mandatory | C2: Accounts & Admin | D2: The system shall allow a guest to register by entering name, unique email, password and a mandatory terms-and-privacy consent checkbox. The password must have at least 8 characters, including at least one letter and one digit. The system shall reject the form with an inline error if the email is invalid or already registered, the password breaks these rules, or consent is not given. | F2: Low | G2: M1 | H2: Not Started
A3: ACC-04 | B3: Mandatory | C3: Accounts & Admin | D3: The system shall allow a registered user, admin or moderator to log in with email and password and land on their role's home page. On failure it shall show a generic "invalid email or password" message. Suspended accounts shall see an "account suspended" message. | E3: ACC-01 | F3: Medium | G3: M1 | H3: Not Started
A4: ACC-05 | B4: Mandatory | C4: Accounts & Admin | D4: After 5 consecutive failed login attempts, the system shall lock the account for 15 minutes and show a lockout message. A successful login resets the counter. | E4: ACC-04 | F4: Medium | G4: M1 | H4: Not Started
A5: ACC-06 | B5: Mandatory | C5: Accounts & Admin | D5: The system shall allow a logged-in user to log out, which clears the authentication cookies and revokes the refresh token on the server. A session with no authenticated request for 30 minutes shall expire and require a new login. | E5: ACC-04, NEW-07 | F5: Medium | G5: M1 | H5: Not Started
A6: ACC-08 | B6: Mandatory | C6: Accounts & Admin | D6: The system shall allow a logged-in user to change their password by entering the current password and a new one that meets the rules. | E6: ACC-04 | F6: Low | G6: M1 | H6: Not Started
A7: ACC-09 | B7: Mandatory | C7: Accounts & Admin | D7: The system shall allow any logged-in user to edit name, phone number and preferred currency, saving only if all fields pass validation. | E7: ACC-04 | F7: Low | G7: M1 | H7: Not Started
A8: ACC-10 | B8: Mandatory | C8: Accounts & Admin | D8: The system shall send a guest who attempts a restricted action (book, review, post) to login and return them to that action afterwards. | E8: ACC-04 | F8: Medium | G8: M2 only | H8: Not Started
A9: ACC-11 | B9: Mandatory | C9: Accounts & Admin | D9: The system shall restrict access to bookings and private itineraries to their owner, except that admins may view all bookings (ACC-17) and moderators may view bookings for their own hotel or airline (FLT-29, HTL-22). Unauthorised requests shall be rejected (403/404). | E9: ACC-04 | F9: Medium | G9: M1 | H9: Not Started
A10: ACC-12 | B10: Mandatory | C10: Accounts & Admin | D10: The system shall allow a registered user to deactivate their own account after confirmation. Deactivation is blocked while the user has upcoming Confirmed bookings. A deactivated user cannot log in; their posts and public itineraries are hidden, and their comments and reviews are shown as "Deleted user". | E10: ACC-04, NEW-01 | F10: Medium | G10: M1 | H10: Not Started
A11: ACC-18 | B11: Mandatory | C11: Accounts & Admin | D11: Admin accounts shall be created by seeding at setup; there is no admin self-registration. | E11: ACC-04 | F11: Low | G11: M1 | H11: Not Started
A12: ACC-19 | B12: Mandatory | C12: Cross-cutting | D12: The system shall not store authentication tokens or user credentials in localStorage, sessionStorage or any other JavaScript-accessible storage. Access and refresh tokens shall be issued as httpOnly, Secure, SameSite cookies, and the frontend shall obtain the current user from an /auth/me endpoint. | E12: ACC-04, ACC-06 | F12: Medium | G12: M1 | H12: Not Started
A13: GEN-12 | B13: Mandatory | C13: Cross-cutting | D13: The system shall seed reference data at setup: airports, cities, countries and supported currencies. | F13: Low | G13: M1 | H13: Not Started
A14: GEN-13 | B14: Mandatory | C14: Cross-cutting | D14: All validation, business rules and authorisation shall be enforced by the backend regardless of frontend checks, and passwords shall be stored only as salted hashes. | F14: Medium | G14: M1 | H14: Not Started
A15: ACC-02 | B15: Bonus | C15: Accounts & Admin | D15: The system shall send a verification link by email after registration and block booking until the email is verified. | E15: ACC-01, GEN-01-B | F15: Medium | G15: M1 | H15: Not Started
A16: ACC-07 | B16: Bonus | C16: Accounts & Admin | D16: The system shall allow a user who forgot their password to request a reset link by email; the link expires after 30 minutes, is single-use, is invalidated by a newer request, and the response does not reveal whether the email exists. | E16: ACC-01, GEN-01-B | F16: Medium | G16: M1 | H16: Not Started

Sheet Aabsy
A1: ID | B1: Type | C1: Module | D1: Requirement | E1: Dependencies | F1: Complexity | G1: Milestone | H1: Status
A2: FLT-11 | B2: Mandatory | C2: Flights | D2: The system shall allow a guest or registered user to search flights by selecting a departure airport, arrival airport, departure date (local date at the departure airport) and number of passengers; list Scheduled flights of active airlines on that date whose available seats (total - booked - held) are sufficient; allow the user to select a flight and cabin category to continue; or show "no flights found" when no match exists. | E2: FLT-02, FLT-03, FLT-04, FLT-22 | F2: High | G2: M1 | H2: Not Started
A3: FLT-12 | B3: Mandatory | C3: Flights | D3: The system shall support: (a) round-trip search returning outbound and return options, booked as one booking with two segments, one payment and one reference, and cancelled as a whole using the outbound segment's tier; (b) passenger types adult (12+), child (2-11) and infant (<2): adults and children pay the cabin fare and occupy a seat, infants pay 10% of the fare and occupy no seat, each booking needs at least one adult and no more infants than adults, and the type is validated against the date of birth (FLT-19); (c) an optional cabin-class filter in search. | E3: FLT-11, FLT-19 | F3: High | G3: M1 | H3: Not Started
A4: FLT-15 | B4: Mandatory | C4: Flights | D4: The system shall allow a guest or registered user to filter flight results by an inclusive minimum and maximum price while preserving the other search criteria, show an error if min > max, and sort results by price, duration or departure time. | E4: FLT-11 | F4: Medium | G4: M1 | H4: Not Started
A5: FLT-17 | B5: Mandatory | C5: Flights | D5: The system shall provide a flight details page showing airline, flight number, airports, local departure and arrival times, duration, each cabin category with price, seats remaining and baggage allowance, and the airline's cancellation policy. | E5: FLT-11 | F5: Low | G5: M1 | H5: Not Started
A6: FLT-19 | B6: Mandatory | C6: Flights | D6: The system shall allow a registered user, during booking, to enter each passenger's full name, date of birth and passport/ID number and optionally add extra baggage (bags and weight) per passenger up to the airline's maximum, with any baggage fee added to the booking total. | E6: FLT-11, FLT-08 | F6: Medium | G6: M1 | H6: Not Started
A7: FLT-21 | B7: Mandatory | C7: Flights | D7: The system shall show a booking summary (flight, passengers, baggage, total) before payment. | E7: FLT-19 | F7: Low | G7: M1 | H7: Not Started
A8: FLT-22 | B8: Mandatory | C8: Flights | D8: When a user proceeds to payment, the system shall atomically reserve the requested seats only if enough remain, creating a booking in Pending Payment status held for 10 minutes. If payment does not succeed within the hold, the booking becomes Expired and the seats are released. Concurrent requests shall never result in more seats booked than available. | E8: FLT-11, NEW-01 | F8: High | G8: M1 | H8: Not Started
A9: FLT-23 | B9: Mandatory | C9: Flights | D9: After successful payment, the system shall set the flight booking to Confirmed, convert the held seats into booked seats, generate a unique booking reference, show a confirmation page, send an in-app notification with the booking details, and offer a downloadable e-ticket (PDF). | E9: FLT-21, FLT-22, PAY-01, PAY-02, GEN-01 | F9: Medium | G9: M1 | H9: Not Started
A10: FLT-25 | B10: Mandatory | C10: Flights | D10: The system shall allow a registered user to view their flight bookings grouped as Upcoming, Past and Cancelled, showing reference, flight, date, passengers, cabin and status, and to open full details. | E10: FLT-23 | F10: Low | G10: M1 | H10: Not Started
A11: FLT-26 | B11: Mandatory | C11: Flights | D11: The system shall allow a registered user to cancel their own Confirmed flight booking any time before departure, after viewing the refund amount computed from the airline's tiers (FLT-09) and confirming. The booking becomes Cancelled, its seats return to inventory and a refund is created (PAY-03). Cancellation after departure is blocked. | E11: FLT-23, FLT-09, PAY-03 | F11: Medium | G11: M1 | H11: Not Started
A12: GEN-11 | B12: Mandatory | C12: Cross-cutting | D12: Flight bookings and hotel reservations shall follow the lifecycle Pending Payment -> Confirmed -> Completed, with Pending Payment -> Expired (hold timeout) and Confirmed -> Cancelled (user or provider cancellation) as the only other transitions. | E12: FLT-22, HTL-18, PAY-01 | F12: Medium | G12: M1 | H12: Not Started
... A14: FLT-28 | B14: Bonus | C14: Flights | D14: The system shall allow seat selection. | E14: FLT-11 | F14: High | G14: M1 | H14: Not Started

Sheet Memo
A1: ID | B1: Type | C1: Module | D1: Requirement | E1: Dependencies | F1: Complexity | G1: Milestone | H1: Status
A2: HTL-16 | B2: Mandatory | C2: Hotels | D2: The system shall allow a registered user to book one or more available rooms in the same hotel for the same dates in one reservation, assigning adults and children (ages 0-17) to each room, with at least one adult per reservation. No room's guests may exceed its maximum occupancy. The total price is the sum over rooms of nights x that room's price at booking time. | E2: HTL-11, HTL-03, HTL-15 | F2: High | G2: M1 | H2: Not Started
A3: HTL-17 | B3: Mandatory | C3: Hotels | D3: After successful payment, the system shall set the reservation (all its rooms) to Confirmed, generate a unique booking reference, show a confirmation page and send an in-app notification with the reservation details. | E3: HTL-16, PAY-01, PAY-02, GEN-01 | F3: Medium | G3: M1 | H3: Not Started
A4: HTL-18 | B4: Mandatory | C4: Hotels | D4: When a user proceeds to payment, the system shall hold all selected rooms together for 10 minutes as one Pending Payment reservation. If any room overlaps a Confirmed reservation, an unexpired hold or a blocked range, the whole request is rejected and nothing is held. If payment does not succeed within the hold, the reservation becomes Expired and the rooms are released. Dates must satisfy check-out after check-in and check-in not in the past. | E4: HTL-16, NEW-01 | F4: High | G4: M1 | H4: Not Started
A5: HTL-20 | B5: Mandatory | C5: Hotels | D5: The system shall allow a registered user to view their hotel reservations grouped as Upcoming, Past and Cancelled, showing reference, hotel, rooms, dates, guests, total and status, and to open full details. | E5: HTL-17 | F5: Low | G5: M1 | H5: Not Started
A6: HTL-21 | B6: Mandatory | C6: Hotels | D6: The system shall allow a registered user to cancel their own Confirmed reservation as a whole before the check-in date, after viewing the refund computed from the hotel's tiers (HTL-10) on the full total. The reservation becomes Cancelled, all its rooms are released for those dates and a refund is created (PAY-03). Partial cancellation is not supported. | E6: HTL-17, HTL-10, PAY-03 | F6: Medium | G6: M1 | H6: Not Started
A7: HTL-23 | B7: Mandatory | C7: Hotels | D7: A Confirmed reservation becomes Completed once its check-out date has passed. The system shall allow the user to submit one rating (1-5) and an optional review (max 1000 characters) per Completed reservation, regardless of the number of rooms, and later edit or delete it. The hotel's average rating is recalculated accordingly. | E7: HTL-17, NEW-01 | F7: Medium | G7: M1 | H7: Not Started
A8: HTL-24 | B8: Mandatory | C8: Hotels | D8: The system shall allow a guest or registered user to view a hotel's average rating, number of ratings and reviews (newest first, paginated). | E8: HTL-23 | F8: Low | G8: M1 | H8: Not Started
A9: PAY-01 | B9: Mandatory | C9: Payments & Policies | D9: The system shall allow a registered user to pay for a Pending Payment flight booking or hotel reservation within its hold period using Stripe in test mode (Stripe Elements / PaymentIntents), so that card details never reach the backend. The booking is confirmed only after the backend verifies that the PaymentIntent succeeded (via Stripe webhook). On failure an error is shown and the user may retry until the hold expires; when the hold expires the PaymentIntent is cancelled. Only the Stripe payment ID, amount, currency and status are stored. | E9: FLT-21, HTL-16, FLT-22, HTL-18 | F9: High | G9: M1 | H9: Not Started
A10: PAY-02 | B10: Mandatory | C10: Payments & Policies | D10: Before payment, the system shall show the provider's policies (airline: cancellation and baggage policies; hotel: cancellation policy and check-in/check-out times) and require an acceptance checkbox. Payment is blocked until accepted, and acceptance is stored with a timestamp. | E10: FLT-04, FLT-08, FLT-09, HTL-09, HTL-10 | F10: Low | G10: M1 | H10: Not Started
A11: PAY-03 | B11: Mandatory | C11: Payments & Policies | D11: For every cancellation with a positive refund amount (user cancellations per the provider's tiers; provider-initiated cancellations at 100%), the system shall issue a refund through the Stripe Refunds API, record it, and show its status (Pending, Refunded, Failed) on the booking details. The user receives an in-app notification. | E11: PAY-01, FLT-09, HTL-10, GEN-01 | F11: Medium | G11: M1 | H11: Not Started
A12: PAY-04 | B12: Mandatory | C12: Payments & Policies | D12: All flight and hotel prices, payments and refunds shall use a single platform currency. | F12: Low | G12: M1 | H12: Not Started
A13: HTL-26 | B13: Bonus | C13: Hotels | D13: The system shall allow a hotel moderator to reply to a review. | E13: HTL-23 | F13: Low | G13: M1 | H13: Not Started

Sheet Moharm
A1: ID | B1: Type | C1: Module | D1: Requirement | E1: Dependencies | F1: Complexity | G1: Milestone | H1: Status
A2: ITN-01 | B2: Mandatory | C2: Itineraries | D2: The system shall allow a registered user to create an itinerary with a required title (max 100 characters), one or more countries selected from a predefined list and a start date; edit its title, countries and start date; and delete it after confirmation. It is private by default. When deleted, it disappears from public search, while clones previously made by other users remain unaffected. | E2: ACC-04, NEW-05 | F2: Low | G2: M1 | H2: Not Started
A3: ITN-03 | B3: Mandatory | C3: Itineraries | D3: The system shall allow a user to list their itineraries (title, countries, start date, days and visibility), most recently updated first, and open any itinerary to view its full details. | E3: ITN-01 | F3: Low | G3: M1 | H3: Not Started
A4: ITN-05 | B4: Mandatory | C4: Itineraries | D4: The system shall allow a user to add days to their itinerary and edit each day's city (selected from the predefined city list shared with hotels and airports) and notes. Days are numbered sequentially, their dates derive from the itinerary start date, and an itinerary has at most 60 days. | E4: ITN-01, NEW-05 | F4: Medium | G4: M1 | H4: Not Started
A5: ITN-07 | B5: Mandatory | C5: Itineraries | D5: The system shall allow a user to delete a day after confirmation. Remaining days are renumbered, and dates and budget totals are recalculated. | E5: ITN-05 | F5: Medium | G5: M1 | H5: Not Started
A6: ITN-08 | B6: Mandatory | C6: Itineraries | D6: The system shall allow a user to move a day to a new position, with days renumbered and dates and groupings recalculated. | E6: ITN-05 | F6: Medium | G6: M1 | H6: Not Started
A7: ITN-09 | B7: Mandatory | C7: Itineraries | D7: The system shall require each itinerary day to have a city and shall display consecutive days in the same city as a group, with the group's day count and budget subtotal. | E7: ITN-05 | F7: Medium | G7: M1 | H7: Not Started
A8: ITN-10 | B8: Mandatory | C8: Itineraries | D8: The system shall allow a user to add, edit and delete activities for an itinerary day, including name, description, optional time and optional cost. | E8: ITN-05 | F8: Low | G8: M1 | H8: Not Started
A9: ITN-12 | B9: Mandatory | C9: Itineraries | D9: The system shall allow a user to attach images to and remove images from an activity under the shared media-upload rule (GEN-08). | E9: ITN-10, GEN-08 | F9: Medium | G9: M1 | H9: Not Started
A10: ITN-14 | B10: Mandatory | C10: Itineraries | D10: The system shall allow a user to add, edit and delete non-negative budget entries for each day across food, accommodation, in-city transport and activities in a selected currency, and show the itinerary's total budget broken down by category and by day. Totals include budget entries, activity costs from ITN-10 (counted under Activities) and intercity transport entries (ITN-16). | E10: ITN-05, ITN-10, ITN-16 | F10: Medium | G10: M1 | H10: Not Started
A11: ITN-16 | B11: Mandatory | C11: Itineraries | D11: The system shall allow a user to add, edit and delete a transport cost entry (mode, from-city, to-city, amount, currency, day). | E11: ITN-05 | F11: Low | G11: M1 | H11: Not Started
A12: ITN-18 | B12: Mandatory | C12: Itineraries | D12: The system shall convert all itinerary budget amounts to the user's preferred currency (from the supported currency list) using exchange rates fetched once per day from a configured public exchange-rate API and cached in the database, and show the rate date. If the API is unavailable, the last cached rates are used. Booking prices are not converted (NEW-04). | E12: ITN-14, ACC-09, NEW-04 | F12: Medium | G12: M1 | H12: Not Started
... A18: ITN-28 | B18: Bonus | C18: Itineraries | D18: The system shall allow a user to export or print an itinerary as PDF. | E18: ITN-03 | F18: Medium | G18: M1 | H18: Not Started

Sheet Hasan
A1: ID | B1: Type | C1: Module | D1: Requirement | E1: Dependencies | F1: Complexity | G1: Milestone | H1: Status
A2: ACC-07a | B2: Mandatory | C2: Accounts & Admin | D2: The system shall allow an admin to reset a user's or moderator's password to a temporary password. The account must set a new password that meets the password rules at its next login. | E2: ACC-04, ACC-14 | F2: Low | G2: M1 | H2: Not Started
A3: ACC-13 | B3: Mandatory | C3: Accounts & Admin | D3: The system shall allow an admin to create a hotel or airline moderator account (name, email, role) linked to exactly one hotel or airline, with a temporary password set by the admin. The moderator must change the password on first login. | E3: ACC-04, FLT-01, HTL-01 | F3: Medium | G3: M1 | H3: Not Started
A4: ACC-14 | B4: Mandatory | C4: Accounts & Admin | D4: The system shall allow an admin to view a paginated list of all accounts (name, email, role, status, registration date) and to search by name or email and filter by role and status. | E4: ACC-04 | F4: Low | G4: M1 | H4: Not Started
A5: ACC-15 | B5: Mandatory | C5: Accounts & Admin | D5: The system shall allow an admin to suspend and reactivate a moderator account (a suspended moderator cannot log in) and, separately, to deactivate and reactivate a hotel or airline. A deactivated provider's listings are hidden from search and cannot be booked; existing Confirmed bookings remain valid. Affected parties receive an in-app notification. | E5: ACC-13, GEN-01 | F5: Medium | G5: M1 | H5: Not Started
A6: ACC-16 | B6: Mandatory | C6: Accounts & Admin | D6: The system shall allow an admin to suspend and reactivate registered users (for example, for abusive content). Suspended users cannot log in, their existing bookings remain valid, and their content stays visible unless hidden through GEN-10. | E6: ACC-14 | F6: Low | G6: M1 | H6: Not Started
A7: ACC-17 | B7: Mandatory | C7: Accounts & Admin | D7: The system shall allow an admin to view a read-only list of all flight and hotel bookings (reference, user, provider, dates, amount, status), filterable by type, status and date range. | E7: FLT-23, HTL-17 | F7: Low | G7: M1 | H7: Not Started
A8: GEN-01 | B8: Mandatory | C8: Cross-cutting | D8: The system shall show in-app notifications (unread count, notification list, mark as read) for booking confirmation, cancellation and refund, flight schedule change, and account or provider suspension. | F8: Medium | G8: M1 | H8: Not Started
A9: GEN-07 | B9: Mandatory | C9: Cross-cutting | D9: The system shall keep an audit log of admin actions (suspensions, deletions). | E9: ACC-15, ACC-16, GEN-10 | F9: Low | G9: M1 | H9: Not Started
A10: GEN-08 | B10: Mandatory | C10: Cross-cutting | D10: The system shall accept image uploads in JPG or PNG format, up to 5 MB each, with up to 5 images per post, activity or hotel and 1 logo per airline, stored on the server and served by URL. Uploads outside these limits are rejected with an error. | F10: Medium | G10: M1 | H10: Not Started
A11: GEN-01-B | B11: Bonus | C11: Cross-cutting | D11: The system shall also send the GEN-01 notifications (plus moderator invitations) by email via SMTP, using a test inbox in development. | E11: GEN-01 | F11: Medium | G11: M1 | H11: Not Started
A12: BON-01 | B12: Bonus | C12: Accounts & Admin | D12: The system shall provide an admin analytics dashboard showing bookings and revenue per provider over a selected period. | E12: ACC-17 | F12: Medium | G12: M1 | H12: Not Started

Sheet Rawda
A1: ID | B1: Type | C1: Module | D1: Requirement | E1: Dependencies | F1: Complexity | G1: Milestone | H1: Status
A2: HTL-01 | B2: Mandatory | C2: Hotels | D2: The system shall allow an admin to create a hotel profile and a hotel moderator to edit their hotel's profile (name, address, city and country, description, photos, star class, amenities). | E2: GEN-08, NEW-05 | F2: Low | G2: M1 | H2: Not Started
A3: HTL-02 | B3: Mandatory | C3: Hotels | D3: The system shall provide a hotel details page showing the hotel profile, photos, amenities, check-in and check-out times, cancellation policy, average rating and reviews, and the available rooms when dates are provided. | E3: HTL-01 | F3: Low | G3: M1 | H3: Not Started
A4: HTL-03 | B4: Mandatory | C4: Hotels | D4: The system shall allow a hotel moderator to add a room (an individually bookable unit) with a room number/name unique within the hotel, type, number of beds, maximum occupancy (>=1) and price per night (>0). | E4: HTL-01 | F4: Low | G4: M1 | H4: Not Started
A5: HTL-04 | B5: Mandatory | C5: Hotels | D5: The system shall allow a hotel moderator to define non-overlapping date ranges when a room is bookable. | E5: HTL-03 | F5: Medium | G5: M1 | H5: Not Started
A6: HTL-05 | B6: Mandatory | C6: Hotels | D6: The system shall allow a hotel moderator to edit a room's beds, occupancy, price and availability. Price changes do not affect existing reservations, and availability cannot be removed for dates with confirmed reservations. | E6: HTL-03 | F6: Medium | G6: M1 | H6: Not Started
A7: HTL-06 | B7: Mandatory | C7: Hotels | D7: The system shall allow a hotel moderator to block date ranges for a room and to deactivate or delete a room. Blocking, deactivation or deletion is rejected if it overlaps any Confirmed or Pending Payment reservation. Deactivated rooms are excluded from search; deletion is allowed only for rooms that have never been reserved. | E7: HTL-04, HTL-03 | F7: Medium | G7: M1 | H7: Not Started
A8: HTL-08 | B8: Mandatory | C8: Hotels | D8: The system shall allow a hotel moderator to view each room's status for a chosen date range as Available, Booked (with reservation reference) or Blocked. | E8: HTL-04 | F8: Medium | G8: M1 | H8: Not Started
A9: HTL-09 | B9: Mandatory | C9: Hotels | D9: The system shall allow a hotel moderator to set the hotel's standard check-in and check-out times, shown on the hotel page and the booking summary. | E9: HTL-01 | F9: Low | G9: M1 | H9: Not Started
A10: HTL-10 | B10: Mandatory | C10: Hotels | D10: The system shall allow a hotel moderator to define cancellation tiers, each with a unique days-before-check-in threshold (integer >=0) and a refund percentage (0-100%), applied with the same selection rule as FLT-09. | E10: HTL-01 | F10: Medium | G10: M1 | H10: Not Started
A11: HTL-11 | B11: Mandatory | C11: Hotels | D11: The system shall allow a guest or registered user to search hotels by city or country, check-in date, check-out date, number of guests and number of rooms (default 1). It shall list active hotels that have at least that many rooms free for the whole stay whose combined maximum occupancy covers the guests. Check-out must be after check-in, and check-in cannot be in the past. | E11: HTL-03, HTL-04, HTL-06, HTL-18 | F11: High | G11: M1 | H11: Not Started
A12: HTL-12 | B12: Mandatory | C12: Hotels | D12: The system shall allow a guest or registered user to filter hotel results by an inclusive minimum and maximum price per night (price of the cheapest qualifying room) and by minimum average rating (1-5; unrated hotels are excluded when a rating filter is set), and sort the results by that price or by rating. | E12: HTL-11, HTL-23 | F12: Medium | G12: M1 | H12: Not Started
... A15: BON-02 | B15: Bonus | C15: Cross-cutting | D15: The system shall allow a registered user to save hotels and public itineraries to a favourites list and view it. | E15: HTL-11, ITN-21 | F15: Low | G15: M1 | H15: Not Started

Sheet Lojy
A1: ID | B1: Type | C1: Module | D1: Requirement | E1: Dependencies | F1: Complexity | G1: Milestone | H1: Status
A2: FLT-01 | B2: Mandatory | C2: Flights | D2: The system shall allow an admin to create an airline profile and an airline moderator to edit their airline's profile (name, code, logo). | E2: GEN-08 | F2: Low | G2: M1 | H2: Not Started
A3: FLT-02 | B3: Mandatory | C3: Flights | D3: The system shall provide a predefined, read-only list of airports (IATA code, name, city, country, IANA time zone) loaded at setup. Flight creation and flight search shall accept only airports from this list. | E3: NEW-05 | F3: Low | G3: M1 | H3: Not Started
A4: FLT-03 | B4: Mandatory | C4: Flights | D4: The system shall allow an airline moderator to create a flight with flight number, departure and arrival airports, and departure and arrival date-times entered in each airport's local time and stored in UTC. It shall reject identical airports, an arrival not after departure (compared in UTC), a departure in the past, and a duplicate flight number for the same airline on the same departure date. | E4: FLT-01, FLT-02 | F4: Medium | G4: M1 | H4: Not Started
A5: FLT-04 | B5: Mandatory | C5: Flights | D5: The system shall allow an airline moderator to define cabin categories per flight from the fixed set {Economy, Premium Economy, Business, First}, each used at most once per flight, with a seat count (whole number, >0), price (>0), free baggage allowance (bag count) and maximum weight (kg) per bag. | E5: FLT-03 | F5: Medium | G5: M1 | H5: Not Started
A6: FLT-05 | B6: Mandatory | C6: Flights | D6: The system shall allow an airline moderator to edit departure/arrival times, cabin prices and cabin seat counts of their own Scheduled flights. Airports cannot be changed once the flight has any booking. Seat counts cannot be reduced below seats already booked or held. Price changes do not affect existing bookings. Any time change sends an in-app notification to passengers with Confirmed bookings. | E6: FLT-03, FLT-04, GEN-01, NEW-02 | F6: Medium | G6: M1 | H6: Not Started
A7: FLT-06 | B7: Mandatory | C7: Flights | D7: The system shall allow an airline moderator to cancel a Scheduled flight after confirmation. The flight becomes Cancelled and is hidden from search; all its Confirmed bookings become Cancelled with a 100% refund (PAY-03); pending seat holds are released; passengers receive an in-app notification. | E7: FLT-23, PAY-03, GEN-01, NEW-02 | F7: Medium | G7: M1 | H7: Not Started
A8: FLT-08 | B8: Mandatory | C8: Flights | D8: The system shall allow an airline moderator to define a price per extra bag (>0) and a maximum number of extra bags per passenger (>=0). Each extra bag has the same maximum weight as the cabin's free baggage allowance. | E8: FLT-04 | F8: Low | G8: M1 | H8: Not Started
A9: FLT-09 | B9: Mandatory | C9: Flights | D9: The system shall allow an airline moderator to define cancellation tiers, each with a unique days-before-departure threshold (integer >=0) and a refund percentage (0-100%). The refund for a cancellation uses the tier with the highest threshold not exceeding the days remaining; if no tier applies, the refund is 0%. | E9: FLT-01 | F9: Medium | G9: M1 | H9: Not Started
A10: FLT-29 | B10: Mandatory | C10: Flights | D10: The system shall allow an airline moderator to view, per flight, its bookings (reference, passenger names, cabin, seats and status: Confirmed or Cancelled), see seats remaining per category, and view or export the passenger list as CSV. | E10: FLT-23 | F10: Low | G10: M1 | H10: Not Started
A11: FLT-30 | B11: Mandatory | C11: Flights | D11: Flights shall have a status of Scheduled, Cancelled or Departed. A flight becomes Departed once its departure time has passed; only Scheduled flights are searchable, editable or bookable. | E11: FLT-03 | F11: Low | G11: M1 | H11: Not Started
A12: GEN-06 | B12: Mandatory | C12: Cross-cutting | D12: The system shall show flight times in each airport's local time zone. | E12: FLT-02, FLT-03 | F12: Medium | G12: M1 | H12: Not Started

Sheet Hafez
A1: ID | B1: Type | C1: Module | D1: Requirement | E1: Dependencies | F1: Complexity | G1: Milestone | H1: Status
A2: BLG-01 | B2: Mandatory | C2: Blog | D2: The system shall allow a registered user to create a post with a required title and body, optional tags and images, and save it as Draft or Publish. Published posts appear in the author's blog and in search. | E2: ACC-04 | F2: Low | G2: M1 | H2: Not Started
A3: BLG-02 | B3: Mandatory | C3: Blog | D3: The system shall allow a guest or registered user to browse a paginated list of published posts filterable by tag, and open a post page showing title, author, date, body, tags, images, like count and comments. Liking, commenting and reporting require login (ACC-10). | E3: BLG-01, BLG-08 | F3: Low | G3: M1 | H3: Not Started
A4: BLG-03 | B4: Mandatory | C4: Blog | D4: The system shall allow a user to list their own posts, including drafts, with title, status, date, like count and comment count. | E4: BLG-01 | F4: Low | G4: M1 | H4: Not Started
A5: BLG-04 | B5: Mandatory | C5: Blog | D5: The system shall allow an author to edit and delete their own posts. | E5: BLG-01 | F5: Low | G5: M1 | H5: Not Started
A6: BLG-05 | B6: Mandatory | C6: Blog | D6: The system shall allow a user to comment on a published post (non-empty, max 500 characters), shown in chronological order. | E6: BLG-01 | F6: Low | G6: M1 | H6: Not Started
A7: BLG-06 | B7: Mandatory | C7: Blog | D7: The system shall allow a user to like a post once and remove the like, showing the like count. | E7: BLG-01 | F7: Low | G7: M1 | H7: Not Started
A8: BLG-07 | B8: Mandatory | C8: Blog | D8: The system shall allow a user to edit and delete their own comments. | E8: BLG-05 | F8: Low | G8: M1 | H8: Not Started
A9: BLG-08 | B9: Mandatory | C9: Blog | D9: The system shall allow an author to add up to 5 tags (max 30 characters each) to a post and edit them later. Tags are searchable and clickable to list matching posts. | E9: BLG-01 | F9: Low | G9: M1 | H9: Not Started
A10: BLG-09 | B10: Mandatory | C10: Blog | D10: The system shall allow a guest or registered user to search published posts by keyword in title, tags or author name, showing title, author, date and excerpt, or "no results". Results are ordered by interaction score (likes + comments) descending, with newest first as a tie-breaker. | E10: BLG-01 | F10: Medium | G10: M1 | H10: Not Started
A11: BLG-10 | B11: Mandatory | C11: Blog | D11: The system shall allow an author to attach images to a post under the shared media-upload rule (GEN-08) and remove them. | E11: BLG-01, GEN-08 | F11: Medium | G11: M1 | H11: Not Started
A12: BLG-12 | B12: Mandatory | C12: Blog | D12: The system shall provide a public author page showing the author's name, join date, published posts and public itineraries. | E12: BLG-01, ITN-20 | F12: Low | G12: M1 | H12: Not Started
... A15: BLG-13 | B15: Bonus | C15: Blog | D15: The system shall allow an author to attach an itinerary to a post. | E15: BLG-01, ITN-03 | F15: Low | G15: M1 | H15: Not Started
